Workbook

Sheet Dashboard
A1: Indian Gaming Platform — Player & Transaction Analytics Dashboard
A4: FILTERS — choose a value, or leave "All" to include every session
A5: Region | D5: Platform | G5: Game Name | J5: Purchase Type | M5: Player Type | P5: Year-Month
A6: All | D6: All | G6: All | J6: All | M6: All | P6: All
A9: Total Sessions | D9: Distinct Players | G9: Total Revenue | J9: ARPU | M9: Suspicious Sessions | P9: Success Rate %
A10: =SUMPRODUCT(('Transformed Data'!$F$5:$F$504=IF($A$6="All",'Transformed Data'!$F$5:$F$504,$A$6))*('Transformed Data'!$E$5:$E$504=IF($D$6="All",'Transformed Data'!$E$5:$E$504,$D$6))*('Transformed Data'!$D$5:$D$504=IF($G$6="All",'Transformed Data'!$D$5:$D$504,$G$6))*('Transformed Data'!$J$5:$J$504=IF($J$6="All",'Transformed Data'!$J$5:$J$504,$J$6))*('Transformed Data'!$L$5:$L$504=IF($M$6="All",'Transformed Data'!$L$5:$L$504,$M$6))*('Transformed Data'!$O$5:$O$504=IF($P$6="All",'Transformed Data'!$O$5:$O$504,$P$6))) -> 500 | D10: =SUMPRODUCT((('Transformed Data'!$F$5:$F$504=IF($A$6="All",'Transformed Data'!$F$5:$F$504,$A$6))*('Transformed Data'!$E$5:$E$504=IF($D$6="All",'Transformed Data'!$E$5:$E$504,$D$6))*('Transformed Data'!$D$5:$D$504=IF($G$6="All",'Transformed Data'!$D$5:$D$504,$G$6))*('Transformed Data'!$J$5:$J$504=IF($J$6="All",'Transformed Data'!$J$5:$J$504,$J$6))*('Transformed Data'!$L$5:$L$504=IF($M$6="All",'Transformed Data'!$L$5:$L$504,$M$6))*('Transformed Data'!$O$5:$O$504=IF($P$6="All",'Transformed Data'!$O$5:$O$504,$P$6)))/COUNTIFS('Transformed Data'!$B$5:$B$504,'Transformed Data'!$B$5:$B$504)) -> 489 | G10: =SUMPRODUCT(('Transformed Data'!$F$5:$F$504=IF($A$6="All",'Transformed Data'!$F$5:$F$504,$A$6))*('Transformed Data'!$E$5:$E$504=IF($D$6="All",'Transformed Data'!$E$5:$E$504,$D$6))*('Transformed Data'!$D$5:$D$504=IF($G$6="All",'Transformed Data'!$D$5:$D$504,$G$6))*('Transformed Data'!$J$5:$J$504=IF($J$6="All",'Transformed Data'!$J$5:$J$504,$J$6))*('Transformed Data'!$L$5:$L$504=IF($M$6="All",'Transformed Data'!$L$5:$L$504,$M$6))*('Transformed Data'!$O$5:$O$504=IF($P$6="All",'Transformed Data'!$O$5:$O$504,$P$6)),'Transformed Data'!$I$5:$I$504) -> 2631.27 | J10: =IF(A10=0,0,G10/A10) -> 5.26254 | M10: =SUMPRODUCT(('Transformed Data'!$F$5:$F$504=IF($A$6="All",'Transformed Data'!$F$5:$F$504,$A$6))*('Transformed Data'!$E$5:$E$504=IF($D$6="All",'Transformed Data'!$E$5:$E$504,$D$6))*('Transformed Data'!$D$5:$D$504=IF($G$6="All",'Transformed Data'!$D$5:$D$504,$G$6))*('Transformed Data'!$J$5:$J$504=IF($J$6="All",'Transformed Data'!$J$5:$J$504,$J$6))*('Transformed Data'!$L$5:$L$504=IF($M$6="All",'Transformed Data'!$L$5:$L$504,$M$6))*('Transformed Data'!$O$5:$O$504=IF($P$6="All",'Transformed Data'!$O$5:$O$504,$P$6))*('Transformed Data'!$N$5:$N$504="Yes")) -> 103 | P10: =SUMPRODUCT(('Transformed Data'!$F$5:$F$504=IF($A$6="All",'Transformed Data'!$F$5:$F$504,$A$6))*('Transformed Data'!$E$5:$E$504=IF($D$6="All",'Transformed Data'!$E$5:$E$504,$D$6))*('Transformed Data'!$D$5:$D$504=IF($G$6="All",'Transformed Data'!$D$5:$D$504,$G$6))*('Transformed Data'!$J$5:$J$504=IF($J$6="All",'Transformed Data'!$J$5:$J$504,$J$6))*('Transformed Data'!$L$5:$L$504=IF($M$6="All",'Transformed Data'!$L$5:$L$504,$M$6))*('Transformed Data'!$O$5:$O$504=IF($P$6="All",'Transformed Data'!$O$5:$O$504,$P$6))*('Transformed Data'!$K$5:$K$504="Completed"))/IF(A10=0,1,A10) -> 0.72
A13: Player Engagement Analysis
A31: Monetization Insights
A49: Platform, Region & Suspicious Behavior Overview
A67: Note: dropdown filters drive the live KPI strip above using formulas, keeping this a portable, plain .xlsx file. Charts read from the fixed Summary Tables. For native click-to-filter Slicers linked to every chart, load Transformed Data into a real Excel PivotTable (Insert > PivotTable) inside Excel itself — Slicers cannot be authored outside the Excel application.

Sheet Summary Tables
A1: Summary Tables — pivot-style aggregations feeding the Dashboard
A2: Built with SUMIFS / COUNTIFS / SUMPRODUCT against Transformed Data (native Excel PivotTables were not used so the workbook stays a plain, portable .xlsx — see README for why).
A4: 1. Monthly Active Players & Sessions
A5: Year-Month | B5: Distinct Players | C5: Total Sessions
A6: 2024-12 | B6: =SUMPRODUCT(('Transformed Data'!$O$5:$O$504=$A6)/COUNTIFS('Transformed Data'!$B$5:$B$504,'Transformed Data'!$B$5:$B$504,'Transformed Data'!$O$5:$O$504,'Transformed Data'!$O$5:$O$504)) -> 48 | C6: =COUNTIFS('Transformed Data'!$O$5:$O$504,$A6) -> 48
A7: 2025-01 | B7: =SUMPRODUCT(('Transformed Data'!$O$5:$O$504=$A7)/COUNTIFS('Transformed Data'!$B$5:$B$504,'Transformed Data'!$B$5:$B$504,'Transformed Data'!$O$5:$O$504,'Transformed Data'!$O$5:$O$504)) -> 95 | C7: =COUNTIFS('Transformed Data'!$O$5:$O$504,$A7) -> 95
A8: 2025-02 | B8: =SUMPRODUCT(('Transformed Data'!$O$5:$O$504=$A8)/COUNTIFS('Transformed Data'!$B$5:$B$504,'Transformed Data'!$B$5:$B$504,'Transformed Data'!$O$5:$O$504,'Transformed Data'!$O$5:$O$504)) -> 77 | C8: =COUNTIFS('Transformed Data'!$O$5:$O$504,$A8) -> 77
A9: 2025-03 | B9: =SUMPRODUCT(('Transformed Data'!$O$5:$O$504=$A9)/COUNTIFS('Transformed Data'!$B$5:$B$504,'Transformed Data'!$B$5:$B$504,'Transformed Data'!$O$5:$O$504,'Transformed Data'!$O$5:$O$504)) -> 66 | C9: =COUNTIFS('Transformed Data'!$O$5:$O$504,$A9) -> 67
A10: 2025-04 | B10: =SUMPRODUCT(('Transformed Data'!$O$5:$O$504=$A10)/COUNTIFS('Transformed Data'!$B$5:$B$504,'Transformed Data'!$B$5:$B$504,'Transformed Data'!$O$5:$O$504,'Transformed Data'!$O$5:$O$504)) -> 75 | C10: =COUNTIFS('Transformed Data'!$O$5:$O$504,$A10) -> 76
A11: 2025-05 | B11: =SUMPRODUCT(('Transformed Data'!$O$5:$O$504=$A11)/COUNTIFS('Transformed Data'!$B$5:$B$504,'Transformed Data'!$B$5:$B$504,'Transformed Data'!$O$5:$O$504,'Transformed Data'!$O$5:$O$504)) -> 101 | C11: =COUNTIFS('Transformed Data'!$O$5:$O$504,$A11) -> 101
A12: 2025-06 | B12: =SUMPRODUCT(('Transformed Data'!$O$5:$O$504=$A12)/COUNTIFS('Transformed Data'!$B$5:$B$504,'Transformed Data'!$B$5:$B$504,'Transformed Data'!$O$5:$O$504,'Transformed Data'!$O$5:$O$504)) -> 36 | C12: =COUNTIFS('Transformed Data'!$O$5:$O$504,$A12) -> 36
A14: 2. Session Count by Engagement Level
A15: Engagement Level | B15: Session Count | C15: % of Sessions
A16: Low | B16: =COUNTIFS('Transformed Data'!$P$5:$P$504,$A16) -> 41 | C16: =B16/500 -> 0.082
A17: Medium | B17: =COUNTIFS('Transformed Data'!$P$5:$P$504,$A17) -> 133 | C17: =B17/500 -> 0.266
A18: High | B18: =COUNTIFS('Transformed Data'!$P$5:$P$504,$A18) -> 326 | C18: =B18/500 -> 0.652
A20: 3. Made Purchase vs Did Not
A21: Made Purchase | B21: Session Count | C21: % of Sessions
A22: Yes | B22: =COUNTIFS('Transformed Data'!$Q$5:$Q$504,$A22) -> 104 | C22: =B22/500 -> 0.208
A23: No | B23: =COUNTIFS('Transformed Data'!$Q$5:$Q$504,$A23) -> 396 | C23: =B23/500 -> 0.792
A25: 4. Monthly Purchases Trend (Made Purchase: Yes vs No)
A26: Year-Month | B26: Purchased (Yes) | C26: Did Not Purchase (No)
A27: 2024-12 | B27: =COUNTIFS('Transformed Data'!$O$5:$O$504,$A27,'Transformed Data'!$Q$5:$Q$504,"Yes") -> 9 | C27: =COUNTIFS('Transformed Data'!$O$5:$O$504,$A27,'Transformed Data'!$Q$5:$Q$504,"No") -> 39
A28: 2025-01 | B28: =COUNTIFS('Transformed Data'!$O$5:$O$504,$A28,'Transformed Data'!$Q$5:$Q$504,"Yes") -> 18 | C28: =COUNTIFS('Transformed Data'!$O$5:$O$504,$A28,'Transformed Data'!$Q$5:$Q$504,"No") -> 77
A29: 2025-02 | B29: =COUNTIFS('Transformed Data'!$O$5:$O$504,$A29,'Transformed Data'!$Q$5:$Q$504,"Yes") -> 21 | C29: =COUNTIFS('Transformed Data'!$O$5:$O$504,$A29,'Transformed Data'!$Q$5:$Q$504,"No") -> 56
A30: 2025-03 | B30: =COUNTIFS('Transformed Data'!$O$5:$O$504,$A30,'Transformed Data'!$Q$5:$Q$504,"Yes") -> 12 | C30: =COUNTIFS('Transformed Data'!$O$5:$O$504,$A30,'Transformed Data'!$Q$5:$Q$504,"No") -> 55
A31: 2025-04 | B31: =COUNTIFS('Transformed Data'!$O$5:$O$504,$A31,'Transformed Data'!$Q$5:$Q$504,"Yes") -> 16 | C31: =COUNTIFS('Transformed Data'!$O$5:$O$504,$A31,'Transformed Data'!$Q$5:$Q$504,"No") -> 60
A32: 2025-05 | B32: =COUNTIFS('Transformed Data'!$O$5:$O$504,$A32,'Transformed Data'!$Q$5:$Q$504,"Yes") -> 20 | C32: =COUNTIFS('Transformed Data'!$O$5:$O$504,$A32,'Transformed Data'!$Q$5:$Q$504,"No") -> 81
A33: 2025-06 | B33: =COUNTIFS('Transformed Data'!$O$5:$O$504,$A33,'Transformed Data'!$Q$5:$Q$504,"Yes") -> 8 | C33: =COUNTIFS('Transformed Data'!$O$5:$O$504,$A33,'Transformed Data'!$Q$5:$Q$504,"No") -> 28
A35: 5. Suspicious Activity by Engagement Level
A36: Engagement Level | B36: Suspicious Sessions | C36: Normal Sessions
A37: Low | B37: =COUNTIFS('Transformed Data'!$P$5:$P$504,$A37,'Transformed Data'!$N$5:$N$504,"Yes") -> 1 | C37: =COUNTIFS('Transformed Data'!$P$5:$P$504,$A37,'Transformed Data'!$N$5:$N$504,"No") -> 40
A38: Medium | B38: =COUNTIFS('Transformed Data'!$P$5:$P$504,$A38,'Transformed Data'!$N$5:$N$504,"Yes") -> 4 | C38: =COUNTIFS('Transformed Data'!$P$5:$P$504,$A38,'Transformed Data'!$N$5:$N$504,"No") -> 129
A39: High | B39: =COUNTIFS('Transformed Data'!$P$5:$P$504,$A39,'Transformed Data'!$N$5:$N$504,"Yes") -> 98 | C39: =COUNTIFS('Transformed Data'!$P$5:$P$504,$A39,'Transformed Data'!$N$5:$N$504,"No") -> 228
A41: 6. Suspicious Sessions Over Time
A42: Year-Month | B42: Suspicious Sessions | C42: Suspicious Rate %
A43: 2024-12 | B43: =COUNTIFS('Transformed Data'!$O$5:$O$504,$A43,'Transformed Data'!$N$5:$N$504,"Yes") -> 15 | C43: =IF(COUNTIFS('Transformed Data'!$O$5:$O$504,$A43)=0,0,B43/COUNTIFS('Transformed Data'!$O$5:$O$504,$A43)) -> 0.3125
A44: 2025-01 | B44: =COUNTIFS('Transformed Data'!$O$5:$O$504,$A44,'Transformed Data'!$N$5:$N$504,"Yes") -> 18 | C44: =IF(COUNTIFS('Transformed Data'!$O$5:$O$504,$A44)=0,0,B44/COUNTIFS('Transformed Data'!$O$5:$O$504,$A44)) -> 0.18947368
A45: 2025-02 | B45: =COUNTIFS('Transformed Data'!$O$5:$O$504,$A45,'Transformed Data'!$N$5:$N$504,"Yes") -> 13 | C45: =IF(COUNTIFS('Transformed Data'!$O$5:$O$504,$A45)=0,0,B45/COUNTIFS('Transformed Data'!$O$5:$O$504,$A45)) -> 0.16883117
A46: 2025-03 | B46: =COUNTIFS('Transformed Data'!$O$5:$O$504,$A46,'Transformed Data'!$N$5:$N$504,"Yes") -> 16 | C46: =IF(COUNTIFS('Transformed Data'!$O$5:$O$504,$A46)=0,0,B46/COUNTIFS('Transformed Data'!$O$5:$O$504,$A46)) -> 0.23880597
...

Sheet Transformed Data
A1: Transformed Data — Cleaned Data + derived analysis columns (Step 3)
A2: New columns use the exact formulas specified in the project brief. Feeds the Summary Tables and Dashboard.
A4: Session ID | B4: Player ID | C4: Player Name | D4: Game Name | E4: Platform | F4: Region | G4: Session Date | H4: Session Duration (min) | I4: In-Game Purchase ($) | J4: Purchase Type | K4: Session Status | L4: Player Type | M4: Level Reached | N4: Is Suspicious | O4: Year-Month | P4: Engagement Level | Q4: Made Purchase | R4: Suspicious Flag
A5: ='Cleaned Data'!A5 -> S00001 | B5: ='Cleaned Data'!B5 -> P3652 | C5: ='Cleaned Data'!C5 -> harrisrichard | D5: ='Cleaned Data'!D5 -> BattleZone | E5: ='Cleaned Data'!E5 -> Console | F5: ='Cleaned Data'!F5 -> East | G5: ='Cleaned Data'!G5 -> 45696 | H5: ='Cleaned Data'!H5 -> 179 | ... N5: ='Cleaned Data'!N5 -> Yes | O5: =TEXT(G5,"yyyy-mm") -> 2025-02 | P5: =IF(H5<20,"Low",IF(H5<=60,"Medium","High")) -> High | Q5: =IF(I5>0,"Yes","No") -> No | R5: =IF(N5="Yes",1,0) -> 1
A6: ='Cleaned Data'!A6 -> S00002 | B6: ='Cleaned Data'!B6 -> P9981 | C6: ='Cleaned Data'!C6 -> wlee | D6: ='Cleaned Data'!D6 -> Zombie Rush | E6: ='Cleaned Data'!E6 -> Mobile | F6: ='Cleaned Data'!F6 -> Central | G6: ='Cleaned Data'!G6 -> 45642 | H6: ='Cleaned Data'!H6 -> 75 | ... N6: ='Cleaned Data'!N6 -> No | O6: =TEXT(G6,"yyyy-mm") -> 2024-12 | P6: =IF(H6<20,"Low",IF(H6<=60,"Medium","High")) -> High | Q6: =IF(I6>0,"Yes","No") -> Yes | R6: =IF(N6="Yes",1,0) -> 0
A7: ='Cleaned Data'!A7 -> S00003 | B7: ='Cleaned Data'!B7 -> P5280 | C7: ='Cleaned Data'!C7 -> katie47 | D7: ='Cleaned Data'!D7 -> SpeedX | E7: ='Cleaned Data'!E7 -> Console | F7: ='Cleaned Data'!F7 -> East | G7: ='Cleaned Data'!G7 -> 45643 | H7: ='Cleaned Data'!H7 -> 36 | ... N7: ='Cleaned Data'!N7 -> No | O7: =TEXT(G7,"yyyy-mm") -> 2024-12 | P7: =IF(H7<20,"Low",IF(H7<=60,"Medium","High")) -> Medium | Q7: =IF(I7>0,"Yes","No") -> Yes | R7: =IF(N7="Yes",1,0) -> 0
A8: ='Cleaned Data'!A8 -> S00004 | B8: ='Cleaned Data'!B8 -> P2930 | C8: ='Cleaned Data'!C8 -> isaac85 | D8: ='Cleaned Data'!D8 -> Clash of Realms | E8: ='Cleaned Data'!E8 -> Mobile | F8: ='Cleaned Data'!F8 -> Central | G8: ='Cleaned Data'!G8 -> 45820 | H8: ='Cleaned Data'!H8 -> 153 | ... N8: ='Cleaned Data'!N8 -> Yes | O8: =TEXT(G8,"yyyy-mm") -> 2025-06 | P8: =IF(H8<20,"Low",IF(H8<=60,"Medium","High")) -> High | Q8: =IF(I8>0,"Yes","No") -> No | R8: =IF(N8="Yes",1,0) -> 1
A9: ='Cleaned Data'!A9 -> S00005 | B9: ='Cleaned Data'!B9 -> P7925 | C9: ='Cleaned Data'!C9 -> ballarddouglas | D9: ='Cleaned Data'!D9 -> Zombie Rush | E9: ='Cleaned Data'!E9 -> Mobile | F9: ='Cleaned Data'!F9 -> North | G9: ='Cleaned Data'!G9 -> 45798 | H9: ='Cleaned Data'!H9 -> 109 | ... N9: ='Cleaned Data'!N9 -> No | O9: =TEXT(G9,"yyyy-mm") -> 2025-05 | P9: =IF(H9<20,"Low",IF(H9<=60,"Medium","High")) -> High | Q9: =IF(I9>0,"Yes","No") -> Yes | R9: =IF(N9="Yes",1,0) -> 0
A10: ='Cleaned Data'!A10 -> S00006 | B10: ='Cleaned Data'!B10 -> P9919 | C10: ='Cleaned Data'!C10 -> lrichardson | D10: ='Cleaned Data'!D10 -> Zombie Rush | E10: ='Cleaned Data'!E10 -> Mobile | F10: ='Cleaned Data'!F10 -> North | G10: ='Cleaned Data'!G10 -> 45743 | H10: ='Cleaned Data'!H10 -> 46 | ... N10: ='Cleaned Data'!N10 -> No | O10: =TEXT(G10,"yyyy-mm") -> 2025-03 | P10: =IF(H10<20,"Low",IF(H10<=60,"Medium","High")) -> Medium | Q10: =IF(I10>0,"Yes","No") -> No | R10: =IF(N10="Yes",1,0) -> 0
A11: ='Cleaned Data'!A11 -> S00007 | B11: ='Cleaned Data'!B11 -> P7231 | C11: ='Cleaned Data'!C11 -> holmesbruce | D11: ='Cleaned Data'!D11 -> Clash of Realms | E11: ='Cleaned Data'!E11 -> Console | F11: ='Cleaned Data'!F11 -> North-East | G11: ='Cleaned Data'!G11 -> 45759 | H11: ='Cleaned Data'!H11 -> 134 | ... N11: ='Cleaned Data'!N11 -> Yes | O11: =TEXT(G11,"yyyy-mm") -> 2025-04 | P11: =IF(H11<20,"Low",IF(H11<=60,"Medium","High")) -> High | Q11: =IF(I11>0,"Yes","No") -> Yes | R11: =IF(N11="Yes",1,0) -> 1
A12: ='Cleaned Data'!A12 -> S00008 | B12: ='Cleaned Data'!B12 -> P5965 | C12: ='Cleaned Data'!C12 -> lhansen | D12: ='Cleaned Data'!D12 -> BattleZone | E12: ='Cleaned Data'!E12 -> PC | F12: ='Cleaned Data'!F12 -> South | G12: ='Cleaned Data'!G12 -> 45666 | H12: ='Cleaned Data'!H12 -> 38 | ... N12: ='Cleaned Data'!N12 -> No | O12: =TEXT(G12,"yyyy-mm") -> 2025-01 | P12: =IF(H12<20,"Low",IF(H12<=60,"Medium","High")) -> Medium | Q12: =IF(I12>0,"Yes","No") -> No | R12: =IF(N12="Yes",1,0) -> 0
A13: ='Cleaned Data'!A13 -> S00009 | B13: ='Cleaned Data'!B13 -> P3834 | C13: ='Cleaned Data'!C13 -> alexis47 | D13: ='Cleaned Data'!D13 -> Clash of Realms | E13: ='Cleaned Data'!E13 -> PC | F13: ='Cleaned Data'!F13 -> East | G13: ='Cleaned Data'!G13 -> 45695 | H13: ='Cleaned Data'!H13 -> 24 | ... N13: ='Cleaned Data'!N13 -> No | O13: =TEXT(G13,"yyyy-mm") -> 2025-02 | P13: =IF(H13<20,"Low",IF(H13<=60,"Medium","High")) -> Medium | Q13: =IF(I13>0,"Yes","No") -> No | R13: =IF(N13="Yes",1,0) -> 0
A14: ='Cleaned Data'!A14 -> S00010 | B14: ='Cleaned Data'!B14 -> P4220 | C14: ='Cleaned Data'!C14 -> ryanmarshall | D14: ='Cleaned Data'!D14 -> Zombie Rush | E14: ='Cleaned Data'!E14 -> PC | F14: ='Cleaned Data'!F14 -> North | G14: ='Cleaned Data'!G14 -> 45791 | H14: ='Cleaned Data'!H14 -> 138 | ... N14: ='Cleaned Data'!N14 -> No | O14: =TEXT(G14,"yyyy-mm") -> 2025-05 | P14: =IF(H14<20,"Low",IF(H14<=60,"Medium","High")) -> High | Q14: =IF(I14>0,"Yes","No") -> No | R14: =IF(N14="Yes",1,0) -> 0
A15: ='Cleaned Data'!A15 -> S00011 | B15: ='Cleaned Data'!B15 -> P1038 | C15: ='Cleaned Data'!C15 -> alexandriaparrish | D15: ='Cleaned Data'!D15 -> SpeedX | E15: ='Cleaned Data'!E15 -> Console | F15: ='Cleaned Data'!F15 -> North | G15: ='Cleaned Data'!G15 -> 45756 | H15: ='Cleaned Data'!H15 -> 26 | ... N15: ='Cleaned Data'!N15 -> No | O15: =TEXT(G15,"yyyy-mm") -> 2025-04 | P15: =IF(H15<20,"Low",IF(H15<=60,"Medium","High")) -> Medium | Q15: =IF(I15>0,"Yes","No") -> No | R15: =IF(N15="Yes",1,0) -> 0
A16: ='Cleaned Data'!A16 -> S00012 | B16: ='Cleaned Data'!B16 -> P7407 | C16: ='Cleaned Data'!C16 -> jacobhaynes | D16: ='Cleaned Data'!D16 -> Zombie Rush | E16: ='Cleaned Data'!E16 -> PC | F16: ='Cleaned Data'!F16 -> North | G16: ='Cleaned Data'!G16 -> 45768 | H16: ='Cleaned Data'!H16 -> 142 | ... N16: ='Cleaned Data'!N16 -> No | O16: =TEXT(G16,"yyyy-mm") -> 2025-04 | P16: =IF(H16<20,"Low",IF(H16<=60,"Medium","High")) -> High | Q16: =IF(I16>0,"Yes","No") -> No | R16: =IF(N16="Yes",1,0) -> 0
... A504: ='Cleaned Data'!A504 -> S00500 | B504: ='Cleaned Data'!B504 -> P4402 | C504: ='Cleaned Data'!C504 -> fnolan | D504: ='Cleaned Data'!D504 -> BattleZone | E504: ='Cleaned Data'!E504 -> Console | F504: ='Cleaned Data'!F504 -> North | G504: ='Cleaned Data'!G504 -> 45656 | H504: ='Cleaned Data'!H504 -> 20 | ... N504: ='Cleaned Data'!N504 -> No | O504: =TEXT(G504,"yyyy-mm") -> 2024-12 | P504: =IF(H504<20,"Low",IF(H504<=60,"Medium","High")) -> Medium | Q504: =IF(I504>0,"Yes","No") -> No | R504: =IF(N504="Yes",1,0) -> 0

Sheet Cleaned Data
A1: Cleaned Data — standardized, QA-checked (see Cleaning Log)
A2: Every cell links back to Raw Data; the only change applied is Purchase Type blanks -> "None" for zero-purchase sessions.
A4: Session ID | B4: Player ID | C4: Player Name | D4: Game Name | E4: Platform | F4: Region | G4: Session Date | H4: Session Duration (min) | I4: In-Game Purchase ($) | J4: Purchase Type | K4: Session Status | L4: Player Type | M4: Level Reached | N4: Is Suspicious
A5: ='Raw Data'!A4 -> S00001 | B5: ='Raw Data'!B4 -> P3652 | C5: ='Raw Data'!C4 -> harrisrichard | D5: ='Raw Data'!D4 -> BattleZone | E5: ='Raw Data'!E4 -> Console | F5: ='Raw Data'!F4 -> East | G5: ='Raw Data'!G4 -> 45696 | H5: ='Raw Data'!H4 -> 179 | I5: ='Raw Data'!I4 -> 0 | J5: =IF('Raw Data'!J4="None","None",IF(ISBLANK('Raw Data'!J4),"None",'Raw Data'!J4)) -> None | K5: ='Raw Data'!K4 -> Completed | L5: ='Raw Data'!L4 -> Free | M5: ='Raw Data'!M4 -> 42 | N5: ='Raw Data'!N4 -> Yes
A6: ='Raw Data'!A5 -> S00002 | B6: ='Raw Data'!B5 -> P9981 | C6: ='Raw Data'!C5 -> wlee | D6: ='Raw Data'!D5 -> Zombie Rush | E6: ='Raw Data'!E5 -> Mobile | F6: ='Raw Data'!F5 -> Central | G6: ='Raw Data'!G5 -> 45642 | H6: ='Raw Data'!H5 -> 75 | I6: ='Raw Data'!I5 -> 26.02 | J6: =IF('Raw Data'!J5="None","None",IF(ISBLANK('Raw Data'!J5),"None",'Raw Data'!J5)) -> Boosters | K6: ='Raw Data'!K5 -> Completed | L6: ='Raw Data'!L5 -> Paid | M6: ='Raw Data'!M5 -> 11 | N6: ='Raw Data'!N5 -> No
A7: ='Raw Data'!A6 -> S00003 | B7: ='Raw Data'!B6 -> P5280 | C7: ='Raw Data'!C6 -> katie47 | D7: ='Raw Data'!D6 -> SpeedX | E7: ='Raw Data'!E6 -> Console | F7: ='Raw Data'!F6 -> East | G7: ='Raw Data'!G6 -> 45643 | H7: ='Raw Data'!H6 -> 36 | I7: ='Raw Data'!I6 -> 2.94 | J7: =IF('Raw Data'!J6="None","None",IF(ISBLANK('Raw Data'!J6),"None",'Raw Data'!J6)) -> Subscriptions | K7: ='Raw Data'!K6 -> Completed | L7: ='Raw Data'!L6 -> Paid | M7: ='Raw Data'!M6 -> 4 | N7: ='Raw Data'!N6 -> No
A8: ='Raw Data'!A7 -> S00004 | B8: ='Raw Data'!B7 -> P2930 | C8: ='Raw Data'!C7 -> isaac85 | D8: ='Raw Data'!D7 -> Clash of Realms | E8: ='Raw Data'!E7 -> Mobile | F8: ='Raw Data'!F7 -> Central | G8: ='Raw Data'!G7 -> 45820 | H8: ='Raw Data'!H7 -> 153 | I8: ='Raw Data'!I7 -> 0 | J8: =IF('Raw Data'!J7="None","None",IF(ISBLANK('Raw Data'!J7),"None",'Raw Data'!J7)) -> None | K8: ='Raw Data'!K7 -> Completed | L8: ='Raw Data'!L7 -> Free | M8: ='Raw Data'!M7 -> 18 | N8: ='Raw Data'!N7 -> Yes
A9: ='Raw Data'!A8 -> S00005 | B9: ='Raw Data'!B8 -> P7925 | C9: ='Raw Data'!C8 -> ballarddouglas | D9: ='Raw Data'!D8 -> Zombie Rush | E9: ='Raw Data'!E8 -> Mobile | F9: ='Raw Data'!F8 -> North | G9: ='Raw Data'!G8 -> 45798 | H9: ='Raw Data'!H8 -> 109 | I9: ='Raw Data'!I8 -> 5.48 | J9: =IF('Raw Data'!J8="None","None",IF(ISBLANK('Raw Data'!J8),"None",'Raw Data'!J8)) -> Boosters | K9: ='Raw Data'!K8 -> Crashed | L9: ='Raw Data'!L8 -> Paid | M9: ='Raw Data'!M8 -> 5 | N9: ='Raw Data'!N8 -> No
A10: ='Raw Data'!A9 -> S00006 | B10: ='Raw Data'!B9 -> P9919 | C10: ='Raw Data'!C9 -> lrichardson | D10: ='Raw Data'!D9 -> Zombie Rush | E10: ='Raw Data'!E9 -> Mobile | F10: ='Raw Data'!F9 -> North | G10: ='Raw Data'!G9 -> 45743 | H10: ='Raw Data'!H9 -> 46 | I10: ='Raw Data'!I9 -> 0 | J10: =IF('Raw Data'!J9="None","None",IF(ISBLANK('Raw Data'!J9),"None",'Raw Data'!J9)) -> None | K10: ='Raw Data'!K9 -> Crashed | L10: ='Raw Data'!L9 -> Free | M10: ='Raw Data'!M9 -> 39 | N10: ='Raw Data'!N9 -> No
A11: ='Raw Data'!A10 -> S00007 | B11: ='Raw Data'!B10 -> P7231 | C11: ='Raw Data'!C10 -> holmesbruce | D11: ='Raw Data'!D10 -> Clash of Realms | E11: ='Raw Data'!E10 -> Console | F11: ='Raw Data'!F10 -> North-East | G11: ='Raw Data'!G10 -> 45759 | H11: ='Raw Data'!H10 -> 134 | I11: ='Raw Data'!I10 -> 42.57 | J11: =IF('Raw Data'!J10="None","None",IF(ISBLANK('Raw Data'!J10),"None",'Raw Data'!J10)) -> Battle Pass | K11: ='Raw Data'!K10 -> Exited Early | L11: ='Raw Data'!L10 -> Paid | M11: ='Raw Data'!M10 -> 40 | N11: ='Raw Data'!N10 -> Yes
A12: ='Raw Data'!A11 -> S00008 | B12: ='Raw Data'!B11 -> P5965 | C12: ='Raw Data'!C11 -> lhansen | D12: ='Raw Data'!D11 -> BattleZone | E12: ='Raw Data'!E11 -> PC | F12: ='Raw Data'!F11 -> South | G12: ='Raw Data'!G11 -> 45666 | H12: ='Raw Data'!H11 -> 38 | I12: ='Raw Data'!I11 -> 0 | J12: =IF('Raw Data'!J11="None","None",IF(ISBLANK('Raw Data'!J11),"None",'Raw Data'!J11)) -> None | K12: ='Raw Data'!K11 -> Exited Early | L12: ='Raw Data'!L11 -> Free | M12: ='Raw Data'!M11 -> 14 | N12: ='Raw Data'!N11 -> No
A13: ='Raw Data'!A12 -> S00009 | B13: ='Raw Data'!B12 -> P3834 | C13: ='Raw Data'!C12 -> alexis47 | D13: ='Raw Data'!D12 -> Clash of Realms | E13: ='Raw Data'!E12 -> PC | F13: ='Raw Data'!F12 -> East | G13: ='Raw Data'!G12 -> 45695 | H13: ='Raw Data'!H12 -> 24 | I13: ='Raw Data'!I12 -> 0 | J13: =IF('Raw Data'!J12="None","None",IF(ISBLANK('Raw Data'!J12),"None",'Raw Data'!J12)) -> None | K13: ='Raw Data'!K12 -> Exited Early | L13: ='Raw Data'!L12 -> Free | M13: ='Raw Data'!M12 -> 45 | N13: ='Raw Data'!N12 -> No
A14: ='Raw Data'!A13 -> S00010 | B14: ='Raw Data'!B13 -> P4220 | C14: ='Raw Data'!C13 -> ryanmarshall | D14: ='Raw Data'!D13 -> Zombie Rush | E14: ='Raw Data'!E13 -> PC | F14: ='Raw Data'!F13 -> North | G14: ='Raw Data'!G13 -> 45791 | H14: ='Raw Data'!H13 -> 138 | I14: ='Raw Data'!I13 -> 0 | J14: =IF('Raw Data'!J13="None","None",IF(ISBLANK('Raw Data'!J13),"None",'Raw Data'!J13)) -> None | K14: ='Raw Data'!K13 -> Exited Early | L14: ='Raw Data'!L13 -> Free | M14: ='Raw Data'!M13 -> 48 | N14: ='Raw Data'!N13 -> No
A15: ='Raw Data'!A14 -> S00011 | B15: ='Raw Data'!B14 -> P1038 | C15: ='Raw Data'!C14 -> alexandriaparrish | D15: ='Raw Data'!D14 -> SpeedX | E15: ='Raw Data'!E14 -> Console | F15: ='Raw Data'!F14 -> North | G15: ='Raw Data'!G14 -> 45756 | H15: ='Raw Data'!H14 -> 26 | I15: ='Raw Data'!I14 -> 0 | J15: =IF('Raw Data'!J14="None","None",IF(ISBLANK('Raw Data'!J14),"None",'Raw Data'!J14)) -> None | K15: ='Raw Data'!K14 -> Crashed | L15: ='Raw Data'!L14 -> Free | M15: ='Raw Data'!M14 -> 27 | N15: ='Raw Data'!N14 -> No
A16: ='Raw Data'!A15 -> S00012 | B16: ='Raw Data'!B15 -> P7407 | C16: ='Raw Data'!C15 -> jacobhaynes | D16: ='Raw Data'!D15 -> Zombie Rush | E16: ='Raw Data'!E15 -> PC | F16: ='Raw Data'!F15 -> North | G16: ='Raw Data'!G15 -> 45768 | H16: ='Raw Data'!H15 -> 142 | I16: ='Raw Data'!I15 -> 0 | J16: =IF('Raw Data'!J15="None","None",IF(ISBLANK('Raw Data'!J15),"None",'Raw Data'!J15)) -> None | K16: ='Raw Data'!K15 -> Completed | L16: ='Raw Data'!L15 -> Free | M16: ='Raw Data'!M15 -> 23 | N16: ='Raw Data'!N15 -> No
... A504: ='Raw Data'!A503 -> S00500 | B504: ='Raw Data'!B503 -> P4402 | C504: ='Raw Data'!C503 -> fnolan | D504: ='Raw Data'!D503 -> BattleZone | E504: ='Raw Data'!E503 -> Console | F504: ='Raw Data'!F503 -> North | G504: ='Raw Data'!G503 -> 45656 | H504: ='Raw Data'!H503 -> 20 | I504: ='Raw Data'!I503 -> 0 | J504: =IF('Raw Data'!J503="None","None",IF(ISBLANK('Raw Data'!J503),"None",'Raw Data'!J503)) -> None | K504: ='Raw Data'!K503 -> Completed | L504: ='Raw Data'!L503 -> Paid | M504: ='Raw Data'!M503 -> 30 | N504: ='Raw Data'!N503 -> No

Sheet Cleaning Log
A1: Step 2: Data Cleaning & Preprocessing — QA Log
A2: All checks run live against Raw Data (500 sessions). Formulas recalculate if the raw data changes.
A4: Check | B4: Method | C4: Result | D4: Status
A5: 1. Duplicate Session IDs | B5: =COUNTA('Raw Data'!A4:A503)-SUMPRODUCT(1/COUNTIF('Raw Data'!A4:A503,'Raw Data'!A4:A503)) -> 0 | C5: =COUNTA('Raw Data'!A4:A503)-SUMPRODUCT(1/COUNTIF('Raw Data'!A4:A503,'Raw Data'!A4:A503)) -> 0 | D5: =IF(C5=0,"PASS","REVIEW") -> PASS
A6: 2. Missing values — Session Date | B6: =COUNTBLANK('Raw Data'!G4:G503) -> 0 | C6: =COUNTBLANK('Raw Data'!G4:G503) -> 0 | D6: =IF(C6=0,"PASS","REVIEW") -> PASS
A7: 3. Missing values — Session Duration | B7: =COUNTBLANK('Raw Data'!H4:H503) -> 0 | C7: =COUNTBLANK('Raw Data'!H4:H503) -> 0 | D7: =IF(C7=0,"PASS","REVIEW") -> PASS
A8: 4. Missing values — In-Game Purchase | B8: =COUNTBLANK('Raw Data'!I4:I503) -> 0 | C8: =COUNTBLANK('Raw Data'!I4:I503) -> 0 | D8: =IF(C8=0,"PASS","REVIEW") -> PASS
A9: 5. Missing values — Platform | B9: =COUNTBLANK('Raw Data'!E4:E503) -> 0 | C9: =COUNTBLANK('Raw Data'!E4:E503) -> 0 | D9: =IF(C9=0,"PASS","REVIEW") -> PASS
A10: 6. Negative Session Duration | B10: =COUNTIFS('Raw Data'!H4:H503,"<0") -> 0 | C10: =COUNTIFS('Raw Data'!H4:H503,"<0") -> 0 | D10: =IF(C10=0,"PASS","REVIEW") -> PASS
A11: 7. Negative In-Game Purchase | B11: =COUNTIFS('Raw Data'!I4:I503,"<0") -> 0 | C11: =COUNTIFS('Raw Data'!I4:I503,"<0") -> 0 | D11: =IF(C11=0,"PASS","REVIEW") -> PASS
A12: 8. Unrealistic Session Duration (>200 min) | B12: =COUNTIFS('Raw Data'!H4:H503,">200") -> 0 | C12: =COUNTIFS('Raw Data'!H4:H503,">200") -> 0 | D12: =IF(C12=0,"PASS","REVIEW") -> PASS
A13: 9. Unrealistic Purchase (>$100) | B13: =COUNTIFS('Raw Data'!I4:I503,">100") -> 0 | C13: =COUNTIFS('Raw Data'!I4:I503,">100") -> 0 | D13: =IF(C13=0,"PASS","REVIEW") -> PASS
A14: 10. Session Date outside Jan-2024 to Jun-2025 | B14: =COUNTIFS('Raw Data'!G4:G503,"<"&DATE(2024,1,1))+COUNTIFS('Raw Data'!G4:G503,">"&DATE(2025,6,30)) -> 0 | C14: =COUNTIFS('Raw Data'!G4:G503,"<"&DATE(2024,1,1))+COUNTIFS('Raw Data'!G4:G503,">"&DATE(2025,6,30)) -> 0 | D14: =IF(C14=0,"PASS","REVIEW") -> PASS
A15: 11. Text formatting variants (Game/Platform/Region/Status/Player Type/Is Suspicious) | B15: =SUMPRODUCT(--(TRIM('Raw Data'!D4:D503)<>'Raw Data'!D4:D503))+SUMPRODUCT(--(TRIM('Raw Data'!E4:E503)<>'Raw Data'!E4:E503))+SUMPRODUCT(--(TRIM('Raw Data'!F4:F503)<>'Raw Data'!F4:F503)) -> 0 | C15: =SUMPRODUCT(--(TRIM('Raw Data'!D4:D503)<>'Raw Data'!D4:D503))+SUMPRODUCT(--(TRIM('Raw Data'!E4:E503)<>'Raw Data'!E4:E503))+SUMPRODUCT(--(TRIM('Raw Data'!F4:F503)<>'Raw Data'!F4:F503)) -> 0 | D15: =IF(C15=0,"PASS","REVIEW") -> PASS
A16: 12. Is Suspicious flag matches AND rule (duration>150 AND purchase>40) — as written in project brief | B16: =SUMPRODUCT(--((('Raw Data'!H4:H503>150)*('Raw Data'!I4:I503>40))<>('Raw Data'!N4:N503="Yes"))) -> 100 | C16: =SUMPRODUCT(--((('Raw Data'!H4:H503>150)*('Raw Data'!I4:I503>40))<>('Raw Data'!N4:N503="Yes"))) -> 100 | D16: =IF(C16=0,"PASS","MISMATCH") -> MISMATCH
A17: 13. Is Suspicious flag matches OR rule (duration>150 OR purchase>40) | B17: =SUMPRODUCT(--((('Raw Data'!H4:H503>150)+('Raw Data'!I4:I503>40)>0)<>('Raw Data'!N4:N503="Yes"))) -> 0 | C17: =SUMPRODUCT(--((('Raw Data'!H4:H503>150)+('Raw Data'!I4:I503>40)>0)<>('Raw Data'!N4:N503="Yes"))) -> 0 | D17: =IF(C17=0,"PASS","REVIEW") -> PASS
A20: Findings & Actions Taken
A21: Duplicates / missing / negative / unrealistic values / out-of-range dates / text-format variants | B21: None found. All checks above return PASS — the raw dataset is already clean on these dimensions.
A22: Purchase Type blank for $0 purchases (396 of 500 rows) | B22: Not a data error — a session with no purchase legitimately has no Purchase Type. Standardized the blank to the label "None" in Cleaned Data for clarity in pivots/filters.
A23: Is Suspicious logic mismatch | B23: The brief's documented rule (duration>150 min AND purchase>$40) does NOT reproduce the actual Is Suspicious flag (100 of 500 rows differ — see Check 12). The flag instead matches an OR rule: duration>150 min OR purchase>$40 (0 mismatches — Check 13). Recommendation: correct the documented business rule to OR before this logic is reused elsewhere; the existing Is Suspicious column itself was trusted as-is for all downstream analysis.
A24: Player ID linked to more than one Player Name | B24: 11 of 489 unique players (~2.2%) have 2 different names recorded across their sessions. Left as-is (ambiguous which name is authoritative) but flagged here for the source system owner to investigate — could indicate shared accounts or a display-name change mid-dataset.

Sheet Raw Data
A1: Raw Data — Indian Gaming Platform Dataset (as supplied, unmodified)
A3: Session ID | B3: Player ID | C3: Player Name | D3: Game Name | E3: Platform | F3: Region | G3: Session Date | H3: Session Duration (min) | I3: In-Game Purchase ($) | J3: Purchase Type | K3: Session Status | L3: Player Type | M3: Level Reached | N3: Is Suspicious
A4: S00001 | B4: P3652 | C4: harrisrichard | D4: BattleZone | E4: Console | F4: East | G4: 45696 | H4: 179 | I4: 0 | K4: Completed | L4: Free | M4: 42 | N4: Yes
A5: S00002 | B5: P9981 | C5: wlee | D5: Zombie Rush | E5: Mobile | F5: Central | G5: 45642 | H5: 75 | I5: 26.02 | J5: Boosters | K5: Completed | L5: Paid | M5: 11 | N5: No
A6: S00003 | B6: P5280 | C6: katie47 | D6: SpeedX | E6: Console | F6: East | G6: 45643 | H6: 36 | I6: 2.94 | J6: Subscriptions | K6: Completed | L6: Paid | M6: 4 | N6: No
A7: S00004 | B7: P2930 | C7: isaac85 | D7: Clash of Realms | E7: Mobile | F7: Central | G7: 45820 | H7: 153 | I7: 0 | K7: Completed | L7: Free | M7: 18 | N7: Yes
A8: S00005 | B8: P7925 | C8: ballarddouglas | D8: Zombie Rush | E8: Mobile | F8: North | G8: 45798 | H8: 109 | I8: 5.48 | J8: Boosters | K8: Crashed | L8: Paid | M8: 5 | N8: No
A9: S00006 | B9: P9919 | C9: lrichardson | D9: Zombie Rush | E9: Mobile | F9: North | G9: 45743 | H9: 46 | I9: 0 | K9: Crashed | L9: Free | M9: 39 | N9: No
A10: S00007 | B10: P7231 | C10: holmesbruce | D10: Clash of Realms | E10: Console | F10: North-East | G10: 45759 | H10: 134 | I10: 42.57 | J10: Battle Pass | K10: Exited Early | L10: Paid | M10: 40 | N10: Yes
A11: S00008 | B11: P5965 | C11: lhansen | D11: BattleZone | E11: PC | F11: South | G11: 45666 | H11: 38 | I11: 0 | K11: Exited Early | L11: Free | M11: 14 | N11: No
A12: S00009 | B12: P3834 | C12: alexis47 | D12: Clash of Realms | E12: PC | F12: East | G12: 45695 | H12: 24 | I12: 0 | K12: Exited Early | L12: Free | M12: 45 | N12: No
A13: S00010 | B13: P4220 | C13: ryanmarshall | D13: Zombie Rush | E13: PC | F13: North | G13: 45791 | H13: 138 | I13: 0 | K13: Exited Early | L13: Free | M13: 48 | N13: No
A14: S00011 | B14: P1038 | C14: alexandriaparrish | D14: SpeedX | E14: Console | F14: North | G14: 45756 | H14: 26 | I14: 0 | K14: Crashed | L14: Free | M14: 27 | N14: No
A15: S00012 | B15: P7407 | C15: jacobhaynes | D15: Zombie Rush | E15: PC | F15: North | G15: 45768 | H15: 142 | I15: 0 | K15: Completed | L15: Free | M15: 23 | N15: No
A16: S00013 | B16: P4776 | C16: xjoseph | D16: SpeedX | E16: Mobile | F16: South | G16: 45724 | H16: 100 | I16: 0 | K16: Completed | L16: Free | M16: 36 | N16: No
A17: S00014 | B17: P6935 | C17: yjohnson | D17: BattleZone | E17: PC | F17: East | G17: 45794 | H17: 78 | I17: 0 | K17: Completed | L17: Free | M17: 35 | N17: No
A18: S00015 | B18: P9150 | C18: lesliemiller | D18: Empire Wars | E18: PC | F18: West | G18: 45719 | H18: 151 | I18: 0 | K18: Completed | L18: Free | M18: 47 | N18: Yes
A19: S00016 | B19: P9796 | C19: raynatalie | D19: BattleZone | E19: Mobile | F19: East | G19: 45664 | H19: 163 | I19: 0 | K19: Completed | L19: Free | M19: 50 | N19: Yes
A20: S00017 | B20: P5317 | C20: xtaylor | D20: BattleZone | E20: PC | F20: East | G20: 45681 | H20: 128 | I20: 0 | K20: Incomplete | L20: Free | M20: 7 | N20: No
A21: S00018 | B21: P5320 | C21: aguilarjennifer | D21: Empire Wars | E21: Console | F21: North-East | G21: 45685 | H21: 173 | I21: 0 | K21: Exited Early | L21: Free | M21: 30 | N21: Yes
A22: S00019 | B22: P8261 | C22: lmeza | D22: SpeedX | E22: Mobile | F22: North | G22: 45769 | H22: 49 | I22: 0 | K22: Exited Early | L22: Free | M22: 47 | N22: No
... A26: S00023 | B26: P4722 | C26: david54 | D26: Zombie Rush | E26: Console | F26: North | G26: 45738 | H26: 58 | I26: 0 | K26: Completed | L26: Free | M26: 37 | N26: No
A27: S00024 | B27: P8146 | C27: rcraig | D27: SpeedX | E27: PC | F27: West | G27: 45740 | H27: 121 | I27: 7.28 | J27: Boosters | K27: Completed | L27: Paid | M27: 34 | N27: No
A28: S00025 | B28: P2146 | C28: kvasquez | D28: Zombie Rush | E28: PC | F28: South | G28: 45781 | H28: 51 | I28: 0 | K28: Crashed | L28: Free | M28: 41 | N28: No
A29: S00026 | B29: P3548 | C29: erica07 | D29: Empire Wars | E29: PC | F29: North-East | G29: 45741 | H29: 96 | I29: 0 | K29: Completed | L29: Paid | M29: 17 | N29: No
A30: S00027 | B30: P2609 | C30: owensoscar | D30: Empire Wars | E30: Mobile | F30: North-East | G30: 45779 | H30: 173 | I30: 0 | K30: Completed | L30: Free | M30: 8 | N30: Yes
A31: S00028 | B31: P4851 | C31: wlawson | D31: SpeedX | E31: Mobile | F31: North-East | G31: 45692 | H31: 105 | I31: 0 | K31: Completed | L31: Free | M31: 11 | N31: No
A32: S00029 | B32: P5046 | C32: kevinruiz | D32: Clash of Realms | E32: Console | F32: North-East | G32: 45763 | H32: 16 | I32: 0 | K32: Completed | L32: Free | M32: 26 | N32: No
A33: S00030 | B33: P4408 | C33: dlee | D33: SpeedX | E33: Mobile | F33: South | G33: 45818 | H33: 135 | I33: 0 | K33: Completed | L33: Free | M33: 12 | N33: No
A34: S00031 | B34: P3683 | C34: rebekah64 | D34: Empire Wars | E34: Mobile | F34: North-East | G34: 45694 | H34: 96 | I34: 0 | K34: Completed | L34: Free | M34: 43 | N34: No
A35: S00032 | B35: P6285 | C35: katherinejohnston | D35: SpeedX | E35: PC | F35: North-East | G35: 45708 | H35: 16 | I35: 0 | K35: Completed | L35: Free | M35: 16 | N35: No
A36: S00033 | B36: P4554 | C36: odavis | D36: Clash of Realms | E36: PC | F36: North-East | G36: 45696 | H36: 165 | I36: 0 | K36: Completed | L36: Free | M36: 23 | N36: Yes
A37: S00034 | B37: P6724 | C37: tylermiller | D37: SpeedX | E37: PC | F37: South | G37: 45797 | H37: 25 | I37: 0 | K37: Crashed | L37: Free | M37: 26 | N37: No
A38: S00035 | B38: P2965 | C38: sonya77 | D38: SpeedX | E38: PC | F38: South | G38: 45729 | H38: 140 | I38: 0 | K38: Completed | L38: Free | M38: 26 | N38: No
A39: S00036 | B39: P4961 | C39: sandyherman | D39: Empire Wars | E39: Mobile | F39: Central | G39: 45750 | H39: 86 | I39: 0 | K39: Completed | L39: Free | M39: 47 | N39: No
... A42: S00039 | B42: P3668 | C42: jenniferwilcox | D42: SpeedX | E42: Mobile | F42: Central | G42: 45702 | H42: 154 | I42: 0 | K42: Completed | L42: Free | M42: 44 | N42: Yes
A43: S00040 | B43: P3875 | C43: bruce09 | D43: SpeedX | E43: PC | F43: North-East | G43: 45673 | H43: 82 | I43: 24.1 | J43: Skins | K43: Completed | L43: Paid | M43: 34 | N43: No
A44: S00041 | B44: P2707 | C44: tpark | D44: Empire Wars | E44: PC | F44: South | G44: 45642 | H44: 49 | I44: 0 | K44: Completed | L44: Free | M44: 9 | N44: No
A45: S00042 | B45: P2683 | C45: csanchez | D45: Clash of Realms | E45: Console | F45: South | G45: 45783 | H45: 35 | I45: 0 | K45: Completed | L45: Paid | M45: 33 | N45: No
A46: S00043 | B46: P2171 | C46: nnguyen | D46: BattleZone | E46: PC | F46: West | G46: 45676 | H46: 112 | I46: 30.74 | J46: Subscriptions | K46: Completed | L46: Paid | M46: 10 | N46: No
...
